Workbook

Sheet Епізоди
A1: № | B1: ФО | C1: Суб'єкт | D1: Дата | E1: Точність дати | F1: Населений пункт | G1: Механізм | H1: Тип епізоду | I1: Напрям відтоку | J1: Опис | K1: Масштаб | L1: Хто заявив | M1: Причина за джерелом | N1: Статус | O1: Причина рішення | P1: Тип джерела | Q1: Джерело 1 | R1: Джерело 2
A2: Республіка Алтай
A3: 1 | B3: СФО | C3: Республіка Алтай | D3: 2024-12-31 | E3: Період | F3: Республіка Алтай | G3: Інше | H3: Статистичні дані | I3: Внутрішній | J3: За 2024 рік республіка — один із трьох регіонів СФО з міграційним ПРИРОСТОМ (+42) | K3: +42 | L3: Росстат | M3: Не названа | N3: Зустрічний знак | O3: Суперечить гіпотезі ТЗ про збільшення відтоку | P3: Регіональне медіа | Q3: https://kvnews.ru/news-feed/omskaya-oblast-voshla-v-pyatrku-regionov-s-samym-bolshim-migratsionnym-ottokom
B4: СФО | C4: Республіка Алтай
B5: СФО | C5: Республіка Алтай
B6: СФО | C6: Республіка Алтай
B7: СФО | C7: Республіка Алтай
A8: Разом | J8: =CONCATENATE("Погоджено: ",COUNTIF(N3:N7,"Погоджено")," · Межових: ",COUNTIF(N3:N7,"Межовий")," · Відкинуто: ",COUNTIF(N3:N7,"Відкинуто")," · Зустрічних: ",COUNTIF(N3:N7,"Зустрічний знак")) | N8: =COUNTIF(N3:N7,"Погоджено")
A10: Алтайський край
B11: СФО | C11: Алтайський край | J11: Епізодів 2026 року не знайдено. Коефіцієнт міграційного приросту 2023 — −0,8 на 10 тис.; помітний відтік молоді в абсолютних числах, але новинних подій цього року немає. | N11: — | P11: Офіційний документ | Q11: https://rosstat.gov.ru/compendium/document/13283
B12: СФО | C12: Алтайський край
B13: СФО | C13: Алтайський край
B14: СФО | C14: Алтайський край
B15: СФО | C15: Алтайський край
A16: Разом | J16: =CONCATENATE("Погоджено: ",COUNTIF(N11:N15,"Погоджено")," · Межових: ",COUNTIF(N11:N15,"Межовий")," · Відкинуто: ",COUNTIF(N11:N15,"Відкинуто")," · Зустрічних: ",COUNTIF(N11:N15,"Зустрічний знак")) | N16: =COUNTIF(N11:N15,"Погоджено")
A18: Тива
A19: 2 | B19: СФО | C19: Тива | D19: 2023-12-31 | E19: Період | F19: Тива | G19: Відтік молоді | H19: Статистичні дані | I19: Внутрішній | J19: Найгірший коефіцієнт міграційного приросту у скоупі — −7,4 на 10 тис. За 2017–2022 республіка втратила 0,40% населення через від'їзд молоді | K19: −7,4 / 10 тис. | L19: Росстат | M19: Не названа | N19: Відкинуто | O19: Поза періодом (2023). Епізодів 2026 року не знайдено — Тива найгірше покрита новинними джерелами | P19: Офіційний документ | Q19: https://rosstat.gov.ru/compendium/document/13283 | R19: https://cyberleninka.ru/article/n/sravnitelnyy-analiz-sotsialno-demograficheskoy-situatsii-v-respublikah-sibirskogo-federalnogo-okruga-altay-tuva-hakasiya
B20: СФО | C20: Тива
B21: СФО | C21: Тива
B22: СФО | C22: Тива
B23: СФО | C23: Тива
A24: Разом | J24: =CONCATENATE("Погоджено: ",COUNTIF(N19:N23,"Погоджено")," · Межових: ",COUNTIF(N19:N23,"Межовий")," · Відкинуто: ",COUNTIF(N19:N23,"Відкинуто")," · Зустрічних: ",COUNTIF(N19:N23,"Зустрічний знак")) | N24: =COUNTIF(N19:N23,"Погоджено")
A26: Хакасія
A27: 3 | B27: СФО | C27: Хакасія | D27: 2024-12-31 | E27: Період | F27: Хакасія | G27: Інше | H27: Статистичні дані | I27: Внутрішній | J27: За 2024 рік республіка — один із трьох регіонів СФО з міграційним ПРИРОСТОМ (+335) | K27: +335 | L27: Росстат | M27: Не названа | N27: Зустрічний знак | O27: Суперечить гіпотезі ТЗ | P27: Регіональне медіа | Q27: https://kvnews.ru/news-feed/omskaya-oblast-voshla-v-pyatrku-regionov-s-samym-bolshim-migratsionnym-ottokom
B28: СФО | C28: Хакасія
B29: СФО | C29: Хакасія
B30: СФО | C30: Хакасія
B31: СФО | C31: Хакасія
A32: Разом | J32: =CONCATENATE("Погоджено: ",COUNTIF(N27:N31,"Погоджено")," · Межових: ",COUNTIF(N27:N31,"Межовий")," · Відкинуто: ",COUNTIF(N27:N31,"Відкинуто")," · Зустрічних: ",COUNTIF(N27:N31,"Зустрічний знак")) | N32: =COUNTIF(N27:N31,"Погоджено")
A34: Красноярський край
B35: СФО | C35: Красноярський край | J35: Епізодів 2026 року не знайдено. За 2023 рік — єдиний із великих сибірських регіонів із міграційним приростом (+3,4 на 10 тис.). | N35: — | P35: Офіційний документ | Q35: https://rosstat.gov.ru/compendium/document/13283
B36: СФО | C36: Красноярський край
B37: СФО | C37: Красноярський край
B38: СФО | C38: Красноярський край
B39: СФО | C39: Красноярський край
A40: Разом | J40: =CONCATENATE("Погоджено: ",COUNTIF(N35:N39,"Погоджено")," · Межових: ",COUNTIF(N35:N39,"Межовий")," · Відкинуто: ",COUNTIF(N35:N39,"Відкинуто")," · Зустрічних: ",COUNTIF(N35:N39,"Зустрічний знак")) | N40: =COUNTIF(N35:N39,"Погоджено")
A42: Іркутська область
A43: 4 | B43: СФО | C43: Іркутська область | D43: 2024-12-31 | E43: Період | F43: Іркутська область | G43: Відтік молоді | H43: Статистичні дані | I43: Внутрішній | J43: Найбільший міграційний спад у Сибірському ФО за 2024 рік — −3 384 особи (за січень–листопад −3 067) | K43: −3 384 | L43: Росстат | M43: Не названа | N43: Відкинуто | O43: Поза періодом (2024) — наведено як база порівняння | P43: Регіональне медіа | Q43: https://kvnews.ru/news-feed/omskaya-oblast-voshla-v-pyatrku-regionov-s-samym-bolshim-migratsionnym-ottokom
A44: 5 | B44: СФО | C44: Іркутська область | D44: 2026-01-01 | E44: Період | F44: Іркутська область | G44: Відтік молоді | H44: Статистичні дані | I44: Внутрішній | J44: Відтік кадрів із області випереджає приплив — регіон втрачає робочу силу швидше, ніж набирає | L44: Аналітики / ЗМІ | M44: Змішана | N44: Погоджено | O44: Дату публікації треба уточнити за джерелом | P44: Регіональне медіа | Q44: https://sia.ru/?action=show_news&id=16828417&section=484
B45: СФО | C45: Іркутська область
...

Sheet Зведення
A1: Суб'єкт | B1: ФО | C1: Погоджено (K3) | D1: Межових | E1: Відкинуто | F1: Зустрічних знаків | G1: Усього рядків
A2: Республіка Алтай | B2: СФО | C2: =COUNTIFS(Епізоди!$C$2:$C$216,$A2,Епізоди!$N$2:$N$216,"Погоджено") | D2: =COUNTIFS(Епізоди!$C$2:$C$216,$A2,Епізоди!$N$2:$N$216,"Межовий") | E2: =COUNTIFS(Епізоди!$C$2:$C$216,$A2,Епізоди!$N$2:$N$216,"Відкинуто") | F2: =COUNTIFS(Епізоди!$C$2:$C$216,$A2,Епізоди!$N$2:$N$216,"Зустрічний знак") | G2: =SUM(C2:F2)
A3: Алтайський край | B3: СФО | C3: =COUNTIFS(Епізоди!$C$2:$C$216,$A3,Епізоди!$N$2:$N$216,"Погоджено") | D3: =COUNTIFS(Епізоди!$C$2:$C$216,$A3,Епізоди!$N$2:$N$216,"Межовий") | E3: =COUNTIFS(Епізоди!$C$2:$C$216,$A3,Епізоди!$N$2:$N$216,"Відкинуто") | F3: =COUNTIFS(Епізоди!$C$2:$C$216,$A3,Епізоди!$N$2:$N$216,"Зустрічний знак") | G3: =SUM(C3:F3)
A4: Тива | B4: СФО | C4: =COUNTIFS(Епізоди!$C$2:$C$216,$A4,Епізоди!$N$2:$N$216,"Погоджено") | D4: =COUNTIFS(Епізоди!$C$2:$C$216,$A4,Епізоди!$N$2:$N$216,"Межовий") | E4: =COUNTIFS(Епізоди!$C$2:$C$216,$A4,Епізоди!$N$2:$N$216,"Відкинуто") | F4: =COUNTIFS(Епізоди!$C$2:$C$216,$A4,Епізоди!$N$2:$N$216,"Зустрічний знак") | G4: =SUM(C4:F4)
A5: Хакасія | B5: СФО | C5: =COUNTIFS(Епізоди!$C$2:$C$216,$A5,Епізоди!$N$2:$N$216,"Погоджено") | D5: =COUNTIFS(Епізоди!$C$2:$C$216,$A5,Епізоди!$N$2:$N$216,"Межовий") | E5: =COUNTIFS(Епізоди!$C$2:$C$216,$A5,Епізоди!$N$2:$N$216,"Відкинуто") | F5: =COUNTIFS(Епізоди!$C$2:$C$216,$A5,Епізоди!$N$2:$N$216,"Зустрічний знак") | G5: =SUM(C5:F5)
A6: Красноярський край | B6: СФО | C6: =COUNTIFS(Епізоди!$C$2:$C$216,$A6,Епізоди!$N$2:$N$216,"Погоджено") | D6: =COUNTIFS(Епізоди!$C$2:$C$216,$A6,Епізоди!$N$2:$N$216,"Межовий") | E6: =COUNTIFS(Епізоди!$C$2:$C$216,$A6,Епізоди!$N$2:$N$216,"Відкинуто") | F6: =COUNTIFS(Епізоди!$C$2:$C$216,$A6,Епізоди!$N$2:$N$216,"Зустрічний знак") | G6: =SUM(C6:F6)
A7: Іркутська область | B7: СФО | C7: =COUNTIFS(Епізоди!$C$2:$C$216,$A7,Епізоди!$N$2:$N$216,"Погоджено") | D7: =COUNTIFS(Епізоди!$C$2:$C$216,$A7,Епізоди!$N$2:$N$216,"Межовий") | E7: =COUNTIFS(Епізоди!$C$2:$C$216,$A7,Епізоди!$N$2:$N$216,"Відкинуто") | F7: =COUNTIFS(Епізоди!$C$2:$C$216,$A7,Епізоди!$N$2:$N$216,"Зустрічний знак") | G7: =SUM(C7:F7)
A8: Кемеровська область | B8: СФО | C8: =COUNTIFS(Епізоди!$C$2:$C$216,$A8,Епізоди!$N$2:$N$216,"Погоджено") | D8: =COUNTIFS(Епізоди!$C$2:$C$216,$A8,Епізоди!$N$2:$N$216,"Межовий") | E8: =COUNTIFS(Епізоди!$C$2:$C$216,$A8,Епізоди!$N$2:$N$216,"Відкинуто") | F8: =COUNTIFS(Епізоди!$C$2:$C$216,$A8,Епізоди!$N$2:$N$216,"Зустрічний знак") | G8: =SUM(C8:F8)
A9: Новосибірська область | B9: СФО | C9: =COUNTIFS(Епізоди!$C$2:$C$216,$A9,Епізоди!$N$2:$N$216,"Погоджено") | D9: =COUNTIFS(Епізоди!$C$2:$C$216,$A9,Епізоди!$N$2:$N$216,"Межовий") | E9: =COUNTIFS(Епізоди!$C$2:$C$216,$A9,Епізоди!$N$2:$N$216,"Відкинуто") | F9: =COUNTIFS(Епізоди!$C$2:$C$216,$A9,Епізоди!$N$2:$N$216,"Зустрічний знак") | G9: =SUM(C9:F9)
A10: Омська область | B10: СФО | C10: =COUNTIFS(Епізоди!$C$2:$C$216,$A10,Епізоди!$N$2:$N$216,"Погоджено") | D10: =COUNTIFS(Епізоди!$C$2:$C$216,$A10,Епізоди!$N$2:$N$216,"Межовий") | E10: =COUNTIFS(Епізоди!$C$2:$C$216,$A10,Епізоди!$N$2:$N$216,"Відкинуто") | F10: =COUNTIFS(Епізоди!$C$2:$C$216,$A10,Епізоди!$N$2:$N$216,"Зустрічний знак") | G10: =SUM(C10:F10)
A11: Томська область | B11: СФО | C11: =COUNTIFS(Епізоди!$C$2:$C$216,$A11,Епізоди!$N$2:$N$216,"Погоджено") | D11: =COUNTIFS(Епізоди!$C$2:$C$216,$A11,Епізоди!$N$2:$N$216,"Межовий") | E11: =COUNTIFS(Епізоди!$C$2:$C$216,$A11,Епізоди!$N$2:$N$216,"Відкинуто") | F11: =COUNTIFS(Епізоди!$C$2:$C$216,$A11,Епізоди!$N$2:$N$216,"Зустрічний знак") | G11: =SUM(C11:F11)
A12: Бурятія | B12: ДФО | C12: =COUNTIFS(Епізоди!$C$2:$C$216,$A12,Епізоди!$N$2:$N$216,"Погоджено") | D12: =COUNTIFS(Епізоди!$C$2:$C$216,$A12,Епізоди!$N$2:$N$216,"Межовий") | E12: =COUNTIFS(Епізоди!$C$2:$C$216,$A12,Епізоди!$N$2:$N$216,"Відкинуто") | F12: =COUNTIFS(Епізоди!$C$2:$C$216,$A12,Епізоди!$N$2:$N$216,"Зустрічний знак") | G12: =SUM(C12:F12)
A13: Саха (Якутія) | B13: ДФО | C13: =COUNTIFS(Епізоди!$C$2:$C$216,$A13,Епізоди!$N$2:$N$216,"Погоджено") | D13: =COUNTIFS(Епізоди!$C$2:$C$216,$A13,Епізоди!$N$2:$N$216,"Межовий") | E13: =COUNTIFS(Епізоди!$C$2:$C$216,$A13,Епізоди!$N$2:$N$216,"Відкинуто") | F13: =COUNTIFS(Епізоди!$C$2:$C$216,$A13,Епізоди!$N$2:$N$216,"Зустрічний знак") | G13: =SUM(C13:F13)
... A25: Наскрізні (рівень РФ) | B25: — | C25: =COUNTIFS(Епізоди!$C$2:$C$216,$A25,Епізоди!$N$2:$N$216,"Погоджено") | D25: =COUNTIFS(Епізоди!$C$2:$C$216,$A25,Епізоди!$N$2:$N$216,"Межовий") | E25: =COUNTIFS(Епізоди!$C$2:$C$216,$A25,Епізоди!$N$2:$N$216,"Відкинуто") | F25: =COUNTIFS(Епізоди!$C$2:$C$216,$A25,Епізоди!$N$2:$N$216,"Зустрічний знак") | G25: =SUM(C25:F25)
A26: РАЗОМ | C26: =SUM(C2:C25) | D26: =SUM(D2:D25) | E26: =SUM(E2:E25) | F26: =SUM(F2:F25) | G26: =SUM(G2:G25)
A28: • Числа рахуються формулами COUNTIFS по аркушу «Епізоди» — щойно аналітик змінить статус або допише рядок, зведення оновиться саме.
A29: • «Зустрічний знак» — четвертий статус, якого немає в таблиці K1. Це факти, що СУПЕРЕЧАТЬ гіпотезі ТЗ про збільшення відтоку (міграційний приріст, скорочення відтоку). Їх не можна відкидати: без них звіт буде однобоким.
A30: • Одиниця обліку — епізод, а не людина. Офіційної статистики міграції за 2026 рік не існує: останній бюлетень Росстату — за 2023 рік.
A31: • Оприлюднення статистики у 2026 році вважається епізодом 2026 року, навіть якщо самі дані за 2023–2024. Це закладено в промпт K3.
A32: • У кожному блоці суб'єкта залишено 4 порожні рядки під нові епізоди — вони вже входять у діапазон підрахунку.

Sheet Довідники
A1: Статус | B1: Механізм | C1: Тип епізоду | D1: Напрям відтоку | E1: Причина за джерелом | F1: Точність дати | G1: Тип джерела
A2: Погоджено | B2: Вугільна криза | C2: Закриття підприємства | D2: Внутрішній | E2: Федеральна | F2: Точна | G2: Незалежне медіа
A3: Межовий | B3: Оптимізація соціалки | C3: Закриття / злиття школи | D3: Зовнішній | E3: Регіональна | F3: Місяць | G3: Регіональне медіа
A4: Відкинуто | B4: Бюджетна криза регіонів | C4: Ліквідація населеного пункту | D4: Змішаний | E4: Змішана | F4: Період | G4: Партійне / громадське
A5: Зустрічний знак | B5: Заміщувальна міграція | C5: Визнання посадовця | D5: Н/д | E5: Не названа | F5: Н/д | G5: Державне
B6: Вахтовизація Півночі | C6: Заява депутата | G6: Соцмережа / форум
B7: Мобілізація і війна | C7: Експертна оцінка | G7: Довідкове (вікі)
B8: Структурний відтік Півночі | C8: Статистичні дані | G8: Наукова публікація
B9: Відтік молоді | C9: Від'їзд спеціалістів | G9: Офіційний документ
B10: Інше | C10: Стратегічний документ | G10: Джерело відсутнє
C11: Репортаж ЗМІ
C12: Інше
