Workbook

Sheet Події
A1: № | B1: ФО | C1: Суб'єкт | D1: Дата | E1: Точність дати | F1: Населений пункт | G1: Хвиля | H1: Форма акції | I1: Акція відбулася | J1: Опис | K1: Учасники | L1: Ініціатор | M1: Адресат | N1: Реакція влади | O1: Статус | P1: Причина рішення | Q1: Тип джерела | R1: Джерело 1 | S1: Джерело 2
A2: Республіка Алтай
B3: СФО | C3: Республіка Алтай | J3: За 2026 рік акцій не виявлено. Головний сюжет — муніципальна реформа — вичерпався вуличною фазою червня 2025 (див. блок «Поза скоупом / контекст»). | O3: —
B4: СФО | C4: Республіка Алтай
B5: СФО | C5: Республіка Алтай
B6: СФО | C6: Республіка Алтай
B7: СФО | C7: Республіка Алтай
A8: Разом | J8: =CONCATENATE("Погоджено: ",COUNTIF(O3:O7,"Погоджено")," · Межових: ",COUNTIF(O3:O7,"Межовий")," · Відкинуто: ",COUNTIF(O3:O7,"Відкинуто")) -> Погоджено: 0 · Межових: 0 · Відкинуто: 0 | O8: =COUNTIF(O3:O7,"Погоджено") -> 0
A10: Алтайський край
A11: 1 | B11: СФО | C11: Алтайський край | D11: 2026-03-01 | E11: Період | F11: Барнаул | G11: Блокування інтернету | H11: Відмова в узгодженні | I11: Ні — заборонено | J11: КПРФ подала на мітинг проти політичних репресій і блокувань інтернету. Адміністрація відмовила, заявивши, що політичних репресій у РФ немає, а мітинг пошириться «неправдивою інформацією» | L11: КПРФ | M11: Федеральний | N11: Відмова в узгодженні | O11: Погоджено | Q11: Незалежне медіа | R11: https://novayagazeta.ru/articles/2026/03/10/poshli-v-otkaz
A12: 2 | B12: СФО | C12: Алтайський край | D12: 2026-04-21 | E12: Точна | F12: Алтайський край | G12: Муніципальна реформа | H12: Колективне звернення | I12: Так | J12: Два райони краю виступили проти ліквідації сільрад за ФЗ-33; депутатів опитують повторно після того, як півроку тому губернатор підтримав збереження сільрад | L12: Райради | M12: Федеральний | N12: Немає | O12: Межовий | P12: Інституційний опір органів МСУ, не вулична акція | Q12: Незалежне медіа | R12: https://semnasem.org/news/2026/04/21/dva-rajona-altajskogo-kraya-vystupili-protiv-unichtozheniya-selsovetov-polgoda-nazad-gubernator-podderzhal-ih-sohranenie-no-deputatov-snova-oprashivayut | S12: https://semnasem.org/news/2026/05/12/altajskij-chinovnik-obyasnil-unichtozhenie-selsovetov-zakonom-spisannym-u-nedruzhestvennyh-stran
A13: 3 | B13: СФО | C13: Алтайський край | D13: 2026-05-05 | E13: Точна | F13: Барнаул | G13: Муніципальна реформа | H13: Колективне звернення | I13: Так | J13: Фракція «Справедливої Росії» виступила проти законопроєкту про перетворення районів на муніципальні округи й ліквідацію сільрад на сесії АКЗС | L13: Справедлива Росія | M13: Федеральний | N13: Немає | O13: Межовий | P13: Депутатська заява на сесії, не публічна акція | Q13: Регіональне медіа | R13: https://tolknews.ru/obsestvo/216175-sotsialisti-viskazalis-protiv-munitsipalnoy-reformi-v-altayskom-krae
A14: 4 | B14: СФО | C14: Алтайський край | D14: 2026-08-05 | E14: Точна | F14: Алтайський край | G14: Обмеження права на протест | H14: Інше | I14: Так | J14: Влада краю урізала список офіційних локацій для проведення мітингів і демонстрацій | L14: Влада краю | M14: Регіональний | N14: Обмеження місць для акцій | O14: Погоджено | P14: Реакція влади на протестну активність; виконання федерального курсу на згортання акцій | Q14: Регіональне медіа | R14: https://www.bankfax.ru/news/167162/
A15: 5 | B15: СФО | C15: Алтайський край | D15: 2026-08-15 | E15: Точна | F15: Барнаул | G15: Поза хвилями | H15: Груповий пікет | I15: Так | J15: Узгоджений пікет на площі Свободи з вимогою зупинити будівництво 25-поверхового ЖК «Маяковський-2»; ідеться про навантаження на інфраструктуру й порушення норм забудовником «Селфбуд» | L15: Мешканці | M15: Місцевий | N15: Немає | O15: Відкинуто | P15: Адресат — забудовник і міська влада, федерального виміру немає | Q15: Регіональне медіа | R15: http://habitora.ru/news/zhiteli-barnaula-vyydut-na-piket-15-2026-08-15
B16: СФО | C16: Алтайський край
B17: СФО | C17: Алтайський край
B18: СФО | C18: Алтайський край
B19: СФО | C19: Алтайський край
A20: Разом | J20: =CONCATENATE("Погоджено: ",COUNTIF(O11:O19,"Погоджено")," · Межових: ",COUNTIF(O11:O19,"Межовий")," · Відкинуто: ",COUNTIF(O11:O19,"Відкинуто")) -> Погоджено: 2 · Межових: 2 · Відкинуто: 1 | O20: =COUNTIF(O11:O19,"Погоджено") -> 2
A22: Тива
A23: 6 | B23: СФО | C23: Тива | D23: 2026-01-01 | E23: Період | F23: Кизил | G23: Поза хвилями | H23: Інше | I23: Н/д | J23: Підпал автомобіля «Тойота», що належить громадському діячеві, у дворі житлового будинку по вул. Кочетова, 3 | L23: Невідомі | M23: Місцевий | N23: Немає | O23: Відкинуто | P23: Кримінальна подія, а не протестна акція | Q23: Незалежне медіа | R23: https://risk-inform.com/article_11907.html
A24: 7 | B24: СФО | C24: Тива | D24: 2026-01-01 | E24: Період | F24: Тива | G24: Поза хвилями | H24: Інше | I24: Н/д | J24: Анонімна кампанія у «ВКонтакті» тувинською мовою проти сенатора від Тиви Людмили Нарусової — претензії до її бездіяльності в Раді Федерації | L24: Анонімні автори | M24: Федеральний | N24: Немає | O24: Відкинуто | P24: Дописи в соцмережах прямо виключені визначенням K1 | Q24: Незалежне медіа | R24: https://risk-inform.com/article_11907.html
B25: СФО | C25: Тива
B26: СФО | C26: Тива
B27: СФО | C27: Тива
B28: СФО | C28: Тива
A29: Разом | J29: =CONCATENATE("Погоджено: ",COUNTIF(O23:O28,"Погоджено")," · Межових: ",COUNTIF(O23:O28,"Межовий")," · Відкинуто: ",COUNTIF(O23:O28,"Відкинуто")) -> Погоджено: 0 · Межових: 0 · Відкинуто: 2 | O29: =COUNTIF(O23:O28,"Погоджено") -> 0
A31: Хакасія
A32: 8 | B32: СФО | C32: Хакасія | D32: 2026-07-10 | E32: Точна | F32: Абакан | G32: Поза хвилями | H32: Затримання / штраф | I32: Так | J32: На шістьох мешканців склали протоколи про несанкціонований мітинг за організацію зустрічі любителів занижених автомобілів | K32: 6 | L32: Автолюбителі | M32: Місцевий | N32: Протоколи за ст. 20.2 КпАП | O32: Відкинуто | P32: Зустріч не є протестом; показово як ілюстрація застосування ст. 20.2 | Q32: Незалежне медіа | R32: https://zona.media/news/2026/07/10/abakan
A33: 9 | B33: СФО | C33: Хакасія | D33: 2026-08-08 | E33: Точна | F33: Абакан | G33: Мобілізація і війна | H33: Одиночний пікет | I33: Так | J33: Олена Трофімова вийшла з плакатом «Верните сына! Мобилизован 26.09.22» під час святкування Дня міста на стадіоні. Поліція вилучила плакат, доставила її до відділку й утримувала три години, погрожуючи психлікарнею й тюрмою. Публічно домагається повернення мобілізованих із вересня 2023 | K33: 1 | L33: Низовий | M33: Федеральний | N33: Затримання, 3 год у відділку, вилучення плаката, погрози | O33: Погоджено | Q33: Незалежне медіа | R33: https://semnasem.org/news/2026/08/10/policejskie-v-hakasii-zaderzhala-za-piket-mat-mobilizovannogo-i-ugrozhali-ej-psihdispanserom | S33: https://echofm.online/news/v-hakasii-policziya-zaderzhala-vyshedshuyu-v-piket-mat-mobilizovannogo-ej-ugrozhali-psihiatricheskoj-bolniczej-i-tyurmoj
B34: СФО | C34: Хакасія
B35: СФО | C35: Хакасія
B36: СФО | C36: Хакасія
B37: СФО | C37: Хакасія
A38: Разом | J38: =CONCATENATE("Погоджено: ",COUNTIF(O32:O37,"Погоджено")," · Межових: ",COUNTIF(O32:O37,"Межовий")," · Відкинуто: ",COUNTIF(O32:O37,"Відкинуто")) -> Погоджено: 1 · Межових: 0 · Відкинуто: 1 | O38: =COUNTIF(O32:O37,"Погоджено") -> 1
A40: Красноярський край
B41: СФО | C41: Красноярський край | J41: За 2026 рік акцій не виявлено. Причина названа прямо: у 2025 краю ухвалено закон, що фактично забороняє мітинги; ЛДПР відмовили навіть у мітингу проти заборони мітингів. | O41: — | Q41: Регіональне медіа | R41: https://tvknews.ru/publications/news/84663/
B42: СФО | C42: Красноярський край
B43: СФО | C43: Красноярський край
B44: СФО | C44: Красноярський край
...

Sheet Зведення
A1: Суб'єкт | B1: ФО | C1: Погоджено (K1) | D1: Межових | E1: Відкинуто | F1: Усього рядків
A2: Республіка Алтай | B2: СФО | C2: =COUNTIFS(Події!$C$2:$C$233,$A2,Події!$O$2:$O$233,"Погоджено") -> 0 | D2: =COUNTIFS(Події!$C$2:$C$233,$A2,Події!$O$2:$O$233,"Межовий") -> 0 | E2: =COUNTIFS(Події!$C$2:$C$233,$A2,Події!$O$2:$O$233,"Відкинуто") -> 0 | F2: =SUM(C2:E2) -> 0
A3: Алтайський край | B3: СФО | C3: =COUNTIFS(Події!$C$2:$C$233,$A3,Події!$O$2:$O$233,"Погоджено") -> 2 | D3: =COUNTIFS(Події!$C$2:$C$233,$A3,Події!$O$2:$O$233,"Межовий") -> 2 | E3: =COUNTIFS(Події!$C$2:$C$233,$A3,Події!$O$2:$O$233,"Відкинуто") -> 1 | F3: =SUM(C3:E3) -> 5
A4: Тива | B4: СФО | C4: =COUNTIFS(Події!$C$2:$C$233,$A4,Події!$O$2:$O$233,"Погоджено") -> 0 | D4: =COUNTIFS(Події!$C$2:$C$233,$A4,Події!$O$2:$O$233,"Межовий") -> 0 | E4: =COUNTIFS(Події!$C$2:$C$233,$A4,Події!$O$2:$O$233,"Відкинуто") -> 2 | F4: =SUM(C4:E4) -> 2
A5: Хакасія | B5: СФО | C5: =COUNTIFS(Події!$C$2:$C$233,$A5,Події!$O$2:$O$233,"Погоджено") -> 1 | D5: =COUNTIFS(Події!$C$2:$C$233,$A5,Події!$O$2:$O$233,"Межовий") -> 0 | E5: =COUNTIFS(Події!$C$2:$C$233,$A5,Події!$O$2:$O$233,"Відкинуто") -> 1 | F5: =SUM(C5:E5) -> 2
A6: Красноярський край | B6: СФО | C6: =COUNTIFS(Події!$C$2:$C$233,$A6,Події!$O$2:$O$233,"Погоджено") -> 0 | D6: =COUNTIFS(Події!$C$2:$C$233,$A6,Події!$O$2:$O$233,"Межовий") -> 0 | E6: =COUNTIFS(Події!$C$2:$C$233,$A6,Події!$O$2:$O$233,"Відкинуто") -> 0 | F6: =SUM(C6:E6) -> 0
A7: Іркутська область | B7: СФО | C7: =COUNTIFS(Події!$C$2:$C$233,$A7,Події!$O$2:$O$233,"Погоджено") -> 3 | D7: =COUNTIFS(Події!$C$2:$C$233,$A7,Події!$O$2:$O$233,"Межовий") -> 0 | E7: =COUNTIFS(Події!$C$2:$C$233,$A7,Події!$O$2:$O$233,"Відкинуто") -> 3 | F7: =SUM(C7:E7) -> 6
A8: Кемеровська область | B8: СФО | C8: =COUNTIFS(Події!$C$2:$C$233,$A8,Події!$O$2:$O$233,"Погоджено") -> 0 | D8: =COUNTIFS(Події!$C$2:$C$233,$A8,Події!$O$2:$O$233,"Межовий") -> 0 | E8: =COUNTIFS(Події!$C$2:$C$233,$A8,Події!$O$2:$O$233,"Відкинуто") -> 0 | F8: =SUM(C8:E8) -> 0
A9: Новосибірська область | B9: СФО | C9: =COUNTIFS(Події!$C$2:$C$233,$A9,Події!$O$2:$O$233,"Погоджено") -> 11 | D9: =COUNTIFS(Події!$C$2:$C$233,$A9,Події!$O$2:$O$233,"Межовий") -> 0 | E9: =COUNTIFS(Події!$C$2:$C$233,$A9,Події!$O$2:$O$233,"Відкинуто") -> 0 | F9: =SUM(C9:E9) -> 11
A10: Омська область | B10: СФО | C10: =COUNTIFS(Події!$C$2:$C$233,$A10,Події!$O$2:$O$233,"Погоджено") -> 0 | D10: =COUNTIFS(Події!$C$2:$C$233,$A10,Події!$O$2:$O$233,"Межовий") -> 0 | E10: =COUNTIFS(Події!$C$2:$C$233,$A10,Події!$O$2:$O$233,"Відкинуто") -> 2 | F10: =SUM(C10:E10) -> 2
A11: Томська область | B11: СФО | C11: =COUNTIFS(Події!$C$2:$C$233,$A11,Події!$O$2:$O$233,"Погоджено") -> 1 | D11: =COUNTIFS(Події!$C$2:$C$233,$A11,Події!$O$2:$O$233,"Межовий") -> 0 | E11: =COUNTIFS(Події!$C$2:$C$233,$A11,Події!$O$2:$O$233,"Відкинуто") -> 0 | F11: =SUM(C11:E11) -> 1
A12: Бурятія | B12: ДФО | C12: =COUNTIFS(Події!$C$2:$C$233,$A12,Події!$O$2:$O$233,"Погоджено") -> 3 | D12: =COUNTIFS(Події!$C$2:$C$233,$A12,Події!$O$2:$O$233,"Межовий") -> 0 | E12: =COUNTIFS(Події!$C$2:$C$233,$A12,Події!$O$2:$O$233,"Відкинуто") -> 1 | F12: =SUM(C12:E12) -> 4
A13: Саха (Якутія) | B13: ДФО | C13: =COUNTIFS(Події!$C$2:$C$233,$A13,Події!$O$2:$O$233,"Погоджено") -> 2 | D13: =COUNTIFS(Події!$C$2:$C$233,$A13,Події!$O$2:$O$233,"Межовий") -> 0 | E13: =COUNTIFS(Події!$C$2:$C$233,$A13,Події!$O$2:$O$233,"Відкинуто") -> 0 | F13: =SUM(C13:E13) -> 2
... A25: Поза скоупом / контекст | B25: — | C25: =COUNTIFS(Події!$C$2:$C$233,$A25,Події!$O$2:$O$233,"Погоджено") -> 0 | D25: =COUNTIFS(Події!$C$2:$C$233,$A25,Події!$O$2:$O$233,"Межовий") -> 0 | E25: =COUNTIFS(Події!$C$2:$C$233,$A25,Події!$O$2:$O$233,"Відкинуто") -> 9 | F25: =SUM(C25:E25) -> 9
A26: РАЗОМ | C26: =SUM(C2:C25) -> 30 | D26: =SUM(D2:D25) -> 2 | E26: =SUM(E2:E25) -> 25 | F26: =SUM(F2:F25) -> 57
A28: • Числа рахуються формулами COUNTIFS по аркушу «Події» — щойно аналітик змінить статус або допише подію, зведення оновиться саме.
A29: • «Погоджено» = інцидент зарахований як K1. «Межовий» = потребує рішення щодо адресата. «Відкинуто» = розглянуто й визнано не-K1.
A30: • У кожному блоці суб'єкта на аркуші «Події» залишено 4 порожні рядки під нові події — вони вже входять у діапазон підрахунку.
A31: • Блок «Поза скоупом / контекст» містить події поза 23 суб'єктами або поза періодом 2026 — у підсумок K1 вони не входять.

Sheet Довідники
A1: Статус | B1: Хвиля | C1: Форма акції | D1: Акція відбулася | E1: Адресат | F1: Точність дати
A2: Погоджено | B2: Забій худоби | C2: Мітинг | D2: Так | E2: Федеральний | F2: Точна
A3: Межовий | B3: Блокування інтернету | C3: Одиночний пікет | D3: Ні — заборонено | E3: Регіональний | F3: Місяць
A4: Відкинуто | B4: Утильзбір і податки | C4: Груповий пікет | D4: Ні — лише заявка | E4: Місцевий | F4: Період
B5: Муніципальна реформа | C5: Перекриття дороги | D5: Н/д | E5: Роботодавець | F5: Н/д
B6: Мобілізація і війна | C6: Колективне звернення | E6: Іноземна держава
B7: Тарифи й комуналка | C7: Колективний позов | E7: Змішаний
B8: Обмеження права на протест | C8: Відмова в узгодженні
B9: Поза хвилями | C9: Затримання / штраф
C10: Страйк / голодування
C11: Інше
